<?xml version="1.0" encoding="utf-8"?>
<robot xmlns:xacro="http://www.ros.org/wiki/xacro" name="snake_robot">

    <xacro:property name="PI" value="3.141592653589793"/>

    <xacro:property name="spring_damper" value="1"/>
    <xacro:property name="kp" value="1e+6"/>
    <xacro:property name="kd" value="1.0"/>
    <xacro:property name="mu1" value="0.2"/>
    <xacro:property name="mu2" value="0.2"/>
    <xacro:property name="min_depth" value="0.001"/>

    <xacro:property name="scale" value="0.001 0.001 0.001"/>
    <!--    <xacro:property name="bracket_link" value="$(find snake_sim)/meshes/snake2/snake_bracket_link.stl"/>-->
    <!--    <xacro:property name="wheel_link" value="$(find snake_sim)/meshes/snake2/snake_wheel_link.stl"/>-->
    <xacro:property name="bracket_link" value="package://snake_sim/meshes/snake2/snake_bracket_link.stl"/>
    <xacro:property name="wheel_link" value="package://snake_sim/meshes/snake2/snake_wheel_link.stl"/>

    <xacro:macro name="snake_wheel_link" params="parent
    joint_bracket_name joint_bracket_xyz joint_bracket_rpy
    link_bracket_name joint_wheel_name link_wheel_name
    joint_wheel_axis">

        <joint name="${joint_bracket_name}" type="fixed">
            <origin xyz="${joint_bracket_xyz}" rpy="${joint_bracket_rpy}"/>
            <parent link="${parent}"/>
            <child link="${link_bracket_name}"/>
        </joint>

        <link name="${link_bracket_name}">
            <inertial>
                <origin xyz="-3.4524099e-3  1.3449398e-4 -1.3985376e-2" rpy="0 0 0"/>
                <mass value="4.9106004e-02"/>
                <inertia
                        ixx="4.8761664e-5"
                        ixy="6.6044613e-8"
                        ixz="-4.6318659e-6"
                        iyy="1.9955384e-5"
                        iyz="1.9813386e-7"
                        izz="3.3470948e-5"/>
            </inertial>
            <visual>
                <origin xyz="0 0 0" rpy="0 0 0"/>
                <geometry>
                    <mesh filename="${bracket_link}" scale="${scale}"/>
                </geometry>
                <material name="">
                    <color rgba="1 1 1 1"/>
                </material>
            </visual>
            <collision>
                <origin xyz="0 0 0" rpy="0 0 0"/>
                <geometry>
                    <mesh filename="${bracket_link}" scale="${scale}"/>
                </geometry>
            </collision>
        </link>

        <joint name="${joint_wheel_name}" type="continuous">
            <origin xyz="-0.01 0 -0.03" rpy="-${PI/2} 0 0"/>
            <parent link="${link_bracket_name}"/>
            <child link="${link_wheel_name}"/>
            <axis xyz="${joint_wheel_axis}"/>
        </joint>

        <link name="${link_wheel_name}">
            <inertial>
                <origin xyz="0 2.6764276e-5 0" rpy="0 0 0"/>
                <mass value="1.2013554e-1"/>
                <inertia
                        ixx="2.5258572e-5"
                        ixy="0"
                        ixz="6.6285325e-9"
                        iyy="2.5250883e-5"
                        iyz="0"
                        izz="1.6350105e-5"/>
            </inertial>
            <visual>
                <origin xyz="0 0 0" rpy="0 0 0"/>
                <geometry>
                    <mesh filename="${wheel_link}" scale="${scale}"/>
                </geometry>
                <material name="">
                    <color rgba="1 1 1 1"/>
                </material>
            </visual>
            <collision>
                <origin xyz="0 0 0" rpy="0 0 0"/>
                <geometry>
                    <cylinder radius="0.015" length="0.04"/>
                </geometry>
            </collision>
            <!--            <collision>-->
            <!--                <origin xyz="0 0 0" rpy="0 0 0"/>-->
            <!--                <geometry>-->
            <!--                    <mesh filename="${wheel_link}" scale="${scale}"/>-->
            <!--                </geometry>-->
            <!--            </collision>-->
        </link>

        <gazebo reference="${link_bracket_name}">
            <visual>
                <material>
                    <ambient>0 0.8 0 1</ambient>
                    <diffuse>0 0.8 0 1</diffuse>
                    <specular>0 0.8 0 1</specular>
                </material>
            </visual>

            <collision>
                <surface>
                    <contact>
                        <ode/>
                    </contact>
                    <friction>
                        <ode>
                            <mu>${mu1}</mu>
                            <mu2>${mu2}</mu2>
                        </ode>
                    </friction>
                </surface>
            </collision>

            <kp>${kp}</kp>
            <kd>${kd}</kd>
            <mu1>${mu1}</mu1>
            <mu2>${mu2}</mu2>
            <minDepth>${min_depth}</minDepth>
        </gazebo>
        <gazebo reference="${link_wheel_name}">
            <visual>
                <material>
                    <ambient>0 0.8 0 1</ambient>
                    <diffuse>0 0.8 0 1</diffuse>
                    <specular>0 0.8 0 1</specular>
                </material>
            </visual>

            <collision>
                <surface>
                    <contact>
                        <ode/>
                    </contact>
                    <friction>
                        <ode>
                            <mu>${mu1}</mu>
                            <mu2>${mu2}</mu2>
                        </ode>
                    </friction>
                </surface>
            </collision>

            <kp>${kp}</kp>
            <kd>${kd}</kd>
            <mu1>${mu1}</mu1>
            <mu2>${mu2}</mu2>
            <minDepth>${min_depth}</minDepth>
        </gazebo>

    </xacro:macro>
</robot>